<?xml version="1.0"?>
<robot name="robot">
  <link name="base_link">
    <visual>
      <geometry>
        <box size="0.5 0.4 0.2"/>
	</geometry>
	<origin rpy="0 0 0" xyz="0.0 0 0"/>
    	<material name="white">
		<color rgba=".4 .8 .4 0.7"/>
	</material>
    </visual>
 </link>
<link name="laser">
    <visual>
      <geometry>
        <cylinder length=".2" radius="0.1"/>
      </geometry>
      <material name="red">
        <color rgba="0 1 0 1"/>
      </material>
    </visual>
  </link>
<link name="imu">
<visual>
    <geometry>
    <cylinder length=".2" radius="0.05"/>
    </geometry>
    <material name="blue">
    <color rgba="0 0 1 0.7"/>
    </material>
</visual>
</link>

<joint name="laser_joint" type="continuous">
    <axis xyz="0 0 1"/>
    <parent link="base_link"/>
    <child link="laser"/>
    <origin rpy="0 0 3.1415926" xyz="0.140 0 0.05"/>
    <limit effort="100" velocity="100"/>
    <joint_properties damping="0.0" friction="0.0"/>
  </joint>
<joint name="imu_joint" type="continuous">
    <axis xyz="0 0 1"/>
    <parent link="base_link"/>
    <child link="imu"/>
    <origin rpy="0 0 3.1415926" xyz="-0.03 0 0.1"/>
    <limit effort="100" velocity="100"/>
    <joint_properties damping="0.0" friction="0.0"/>
  </joint>
</robot>
